<?xml version="1.0" encoding="utf-8" ?>
<!-- =================================================================================== -->
<!-- |    This document was autogenerated by xacro from /home/andy/blue_arm_moveit/src/blue_arm_description/urdf/blue_arm.xacro | -->
<!-- |    EDITING THIS FILE BY HAND IS NOT RECOMMENDED                                 | -->
<!-- =================================================================================== -->
<!-- This URDF was automatically created by SolidWorks to URDF Exporter! Originally created by Stephen Brawner (brawner@gmail.com) 
     Commit Version: 1.5.1-0-g916b5db  Build Version: 1.5.7152.31018
     For more information, please see http://wiki.ros.org/sw_urdf_exporter -->
<robot name="blue_arm">
    <physics type="ode">
        <max_step_size>0.001</max_step_size>
        <real_time_factor>0.1</real_time_factor>
        <real_time_update_rate>1000</real_time_update_rate>
        <gravity>0 0 -9.8</gravity>
    </physics>
    <gazebo>
        <plugin filename="libgazebo_ros_control.so" name="gazebo_ros_control">
            <robotNamespace>blue_arm</robotNamespace>
            <robotSimType>gazebo_ros_control/DefaultRobotHWSim</robotSimType>
            <legacyModeNS>true</legacyModeNS>
        </plugin>
    </gazebo>
    <gazebo reference="base_link">
        <mu1>0.2</mu1>
        <mu2>0.2</mu2>
        <material>Gazebo/Blue</material>
        <selfCollide>false</selfCollide>
    </gazebo>
    <gazebo reference="link_1">
        <mu1>0.2</mu1>
        <mu2>0.2</mu2>
        <material>Gazebo/Gray</material>
        <selfCollide>false</selfCollide>
    </gazebo>
    <gazebo reference="link_2">
        <mu1>0.2</mu1>
        <mu2>0.2</mu2>
        <material>Gazebo/Blue</material>
        <selfCollide>false</selfCollide>
    </gazebo>
    <gazebo reference="link_3">
        <mu1>0.2</mu1>
        <mu2>0.2</mu2>
        <material>Gazebo/Gray</material>
        <selfCollide>false</selfCollide>
    </gazebo>
    <gazebo reference="link_4">
        <mu1>0.2</mu1>
        <mu2>0.2</mu2>
        <material>Gazebo/Blue</material>
        <selfCollide>false</selfCollide>
    </gazebo>
    <gazebo reference="link_5">
        <mu1>0.2</mu1>
        <mu2>0.2</mu2>
        <material>Gazebo/Gray</material>
        <selfCollide>false</selfCollide>
    </gazebo>
    <gazebo reference="link_6">
        <mu1>0.2</mu1>
        <mu2>0.2</mu2>
        <material>Gazebo/Blue</material>
        <selfCollide>false</selfCollide>
    </gazebo>
    <gazebo reference="joint_1">
        <implicitSpringDamper>True</implicitSpringDamper>
    </gazebo>
    <gazebo reference="joint_2">
        <implicitSpringDamper>True</implicitSpringDamper>
    </gazebo>
    <gazebo reference="joint_3">
        <implicitSpringDamper>True</implicitSpringDamper>
    </gazebo>
    <gazebo reference="joint_4">
        <implicitSpringDamper>True</implicitSpringDamper>
    </gazebo>
    <gazebo reference="joint_5">
        <implicitSpringDamper>True</implicitSpringDamper>
    </gazebo>
    <gazebo reference="joint_6">
        <implicitSpringDamper>True</implicitSpringDamper>
    </gazebo>
    <gazebo reference="joint_7">
        <implicitSpringDamper>True</implicitSpringDamper>
    </gazebo>
    <!-- parses the transmission tags and loads the appropriate hardware interfaces and controller manager -->
    <!-- <robot xmlns:xacro="http://www.ros.org/wiki/xacro">

  <xacro:macro name="table_arm_transmission" params="side"> -->
    <!-- all joint transmission -->
    <transmission name="transmission_1">
        <type>transmission_interface/SimpleTransmission</type>
        <joint name="joint_1">
            <hardwareInterface>hardware_interface/EffortJointInterface</hardwareInterface>
        </joint>
        <actuator name="motor_1">
            <mechanicalReduction>1</mechanicalReduction>
            <hardwareInterface>hardware_interface/EffortJointInterface</hardwareInterface>
        </actuator>
    </transmission>
    <transmission name="transmission_2">
        <type>transmission_interface/SimpleTransmission</type>
        <joint name="joint_2">
            <hardwareInterface>hardware_interface/EffortJointInterface</hardwareInterface>
        </joint>
        <actuator name="motor_2">
            <mechanicalReduction>1</mechanicalReduction>
            <hardwareInterface>hardware_interface/EffortJointInterface</hardwareInterface>
        </actuator>
    </transmission>
    <transmission name="transmission_3">
        <type>transmission_interface/SimpleTransmission</type>
        <joint name="joint_3">
            <hardwareInterface>hardware_interface/EffortJointInterface</hardwareInterface>
        </joint>
        <actuator name="motor_3">
            <mechanicalReduction>1</mechanicalReduction>
            <hardwareInterface>hardware_interface/EffortJointInterface</hardwareInterface>
        </actuator>
    </transmission>
    <transmission name="transmission_4">
        <type>transmission_interface/SimpleTransmission</type>
        <joint name="joint_4">
            <hardwareInterface>hardware_interface/EffortJointInterface</hardwareInterface>
        </joint>
        <actuator name="motor_4">
            <mechanicalReduction>1</mechanicalReduction>
            <hardwareInterface>hardware_interface/EffortJointInterface</hardwareInterface>
        </actuator>
    </transmission>
    <transmission name="transmission_5">
        <type>transmission_interface/SimpleTransmission</type>
        <joint name="joint_5">
            <hardwareInterface>hardware_interface/EffortJointInterface</hardwareInterface>
        </joint>
        <actuator name="motor_5">
            <mechanicalReduction>1</mechanicalReduction>
            <hardwareInterface>hardware_interface/EffortJointInterface</hardwareInterface>
        </actuator>
    </transmission>
    <transmission name="transmission_6">
        <type>transmission_interface/SimpleTransmission</type>
        <joint name="joint_6">
            <hardwareInterface>hardware_interface/EffortJointInterface</hardwareInterface>
        </joint>
        <actuator name="motor_6">
            <mechanicalReduction>1</mechanicalReduction>
            <hardwareInterface>hardware_interface/EffortJointInterface</hardwareInterface>
        </actuator>
    </transmission>
    <transmission name="transmission_7">
        <type>transmission_interface/SimpleTransmission</type>
        <joint name="joint_7">
            <hardwareInterface>hardware_interface/EffortJointInterface</hardwareInterface>
        </joint>
        <actuator name="motor_7">
            <mechanicalReduction>1</mechanicalReduction>
            <hardwareInterface>hardware_interface/EffortJointInterface</hardwareInterface>
        </actuator>
    </transmission>
    <link name="world" />
    <joint name="joint_0 " type="fixed">
        <origin rpy="0 0 0" xyz="0 0 0" />
        <parent link="world" />
        <child link="base_link" />
    </joint>
    <link name="base_link">
        
<inertial>
            <origin rpy="0 0 0" xyz="-1.2721E-09 -2.221E-09 0.029334" />
            <mass value="0.80823" />
            <inertia ixx="0.00092021" ixy="2.0871E-10" ixz="-1.3863E-11" iyy="0.00088788" iyz="-1.2165E-11" izz="0.001593" />
        </inertial>

        <visual>
            <origin rpy="0 0 0" xyz="0 0 0" />
            <geometry>
                <mesh filename="package://blue_arm_description/meshes/base_link.STL" />
            </geometry>
            <material name="">
                <color rgba="0.1 0.6 0.8 1" />
            </material>
        </visual>
        <collision>
            <origin rpy="0 0 0" xyz="0 0 0" />
            <geometry>
                <mesh filename="package://blue_arm_description/meshes/base_link.STL" />
            </geometry>
        </collision>
    </link>
    <link name="link_1">
        
<inertial>
            <origin rpy="0 0 0" xyz="0.0013724819847024 0.00105856120896306 -0.0137822751691176" />
            <mass value="0.842297822851205" />
            <inertia ixx="0.00076340953424039" ixy="-3.51636077803791E-06" ixz="-3.95975667675045E-06" iyy="0.00121976980344189" iyz="1.36722548032234E-06" izz="0.00102227900722713" />
        </inertial>

        <visual>
            <origin rpy="0 0 0" xyz="0 0 0" />
            <geometry>
                <mesh filename="package://blue_arm_description/meshes/link_1.STL" />
            </geometry>
            <material name="">
                <color rgba="0.898039215686275 0.917647058823529 0.929411764705882 1" />
            </material>
        </visual>
        <collision>
            <origin rpy="0 0 0" xyz="0 0 0" />
            <geometry>
                <mesh filename="package://blue_arm_description/meshes/link_1.STL" />
            </geometry>
        </collision>
    </link>
    <joint name="joint_1" type="revolute">
        <origin rpy="0 0 0" xyz="0 0 0.14" />
        <parent link="base_link" />
        <child link="link_1" />
        <axis xyz="0 0 1" />
        <limit effort="1000" lower="-3.1415926" upper="3.1415926" velocity="6" />
    </joint>
    <link name="link_2">
        
<inertial>
            <origin rpy="0 0 0" xyz="0.0769223200130146 8.08732473817575E-05 -0.00042635625580266" />
            <mass value="0.745981126447571" />
            <inertia ixx="0.000520841610219072" ixy="-4.81334906961203E-06" ixz="-1.95626090273518E-06" iyy="0.00042477641414559" iyz="-5.52016092200821E-06" izz="0.000384489660316636" />
        </inertial>

        <visual>
            <origin rpy="0 0 0" xyz="0 0 0" />
            <geometry>
                <mesh filename="package://blue_arm_description/meshes/link_2.STL" />
            </geometry>
            <material name="">
                <color rgba="0.1 0.6 0.8 1" />
            </material>
        </visual>
        <collision>
            <origin rpy="0 0 0" xyz="0 0 0" />
            <geometry>
                <mesh filename="package://blue_arm_description/meshes/link_2.STL" />
            </geometry>
        </collision>
    </link>
    <joint name="joint_2" type="revolute">
        <origin rpy="0 0 0" xyz="0 0 0" />
        <parent link="link_1" />
        <child link="link_2" />
        <axis xyz="0 -1 0" />
        <limit effort="1000" lower="0" upper="3.1415926" velocity="6" />
    </joint>
    <link name="link_3">
        
<inertial>
            <origin rpy="0 0 0" xyz="-0.0114331813251084 -0.000457582008541844 -0.0216566472730735" />
            <mass value="0.804459827803754" />
            <inertia ixx="0.000394716139862203" ixy="1.20034101751916E-06" ixz="-1.15155911130661E-05" iyy="0.000369176277421544" iyz="-1.52204783481967E-06" izz="0.000335294348916886" />
        </inertial>

        <visual>
            <origin rpy="0 0 0" xyz="0 0 0" />
            <geometry>
                <mesh filename="package://blue_arm_description/meshes/link_3.STL" />
            </geometry>
            <material name="">
                <color rgba="0.898039215686275 0.917647058823529 0.929411764705882 1" />
            </material>
        </visual>
        <collision>
            <origin rpy="0 0 0" xyz="0 0 0" />
            <geometry>
                <mesh filename="package://blue_arm_description/meshes/link_3.STL" />
            </geometry>
        </collision>
    </link>
    <joint name="joint_3" type="revolute">
        <origin rpy="0 0 0" xyz="0.19 0 0" />
        <parent link="link_2" />
        <child link="link_3" />
        <axis xyz="-1 0 0" />
        <limit effort="1000" lower="-3.1415926" upper="3.1415926" velocity="6" />
    </joint>
    <link name="link_4">
        
<inertial>
            <origin rpy="0 0 0" xyz="0.0769734778463645 0.000934629244450365 0.0356212264841299" />
            <mass value="0.566230423072006" />
            <inertia ixx="0.000323477443788715" ixy="1.29185501358438E-06" ixz="-1.18136439524261E-05" iyy="0.000225583796578213" iyz="-6.10063744425435E-06" izz="0.000221671905453137" />
        </inertial>

        <visual>
            <origin rpy="0 0 0" xyz="0 0 0" />
            <geometry>
                <mesh filename="package://blue_arm_description/meshes/link_4.STL" />
            </geometry>
            <material name="">
                <color rgba="0.1 0.6 0.8 1" />
            </material>
        </visual>
        <collision>
            <origin rpy="0 0 0" xyz="0 0 0" />
            <geometry>
                <mesh filename="package://blue_arm_description/meshes/link_4.STL" />
            </geometry>
        </collision>
    </link>
    <joint name="joint_4" type="revolute">
        <origin rpy="0 0 0" xyz="0 0 -0.0365" />
        <parent link="link_3" />
        <child link="link_4" />
        <axis xyz="0 1 0" />
        <limit effort="1000" lower="0" upper="3.1415926" velocity="6" />
    </joint>
    <link name="link_5">
        
<inertial>
            <origin rpy="0 0 0" xyz="-0.0148074583751761 0.00213542128687548 2.18169794868883E-07" />
            <mass value="0.462017126683371" />
            <inertia ixx="0.000177893444569323" ixy="1.32666352831544E-05" ixz="-3.05686863907704E-07" iyy="0.000225592333679048" iyz="1.12464809894113E-09" izz="0.000163107825386613" />
        </inertial>

        <visual>
            <origin rpy="0 0 0" xyz="0 0 0" />
            <geometry>
                <mesh filename="package://blue_arm_description/meshes/link_5.STL" />
            </geometry>
            <material name="">
                <color rgba="0.898039215686275 0.917647058823529 0.929411764705882 1" />
            </material>
        </visual>
        <collision>
            <origin rpy="0 0 0" xyz="0 0 0" />
            <geometry>
                <mesh filename="package://blue_arm_description/meshes/link_5.STL" />
            </geometry>
        </collision>
    </link>
    <joint name="joint_5" type="revolute">
        <origin rpy="0 0 0" xyz="0.183 0 0.0365" />
        <parent link="link_4" />
        <child link="link_5" />
        <axis xyz="-1 0 0" />
        <limit effort="1000" lower="-3.1415926" upper="3.1415926" velocity="6" />
    </joint>
    <link name="link_6">
        
<inertial>
            <origin rpy="0 0 0" xyz="0.057311 -0.0040732 2.7725E-07" />
            <mass value="0.41677" />
            <inertia ixx="0.00018847" ixy="-1.4409E-05" ixz="-1.3757E-09" iyy="0.0001068" iyz="-3.057E-07" izz="0.00014801" />
        </inertial>

        <visual>
            <origin rpy="0 0 0" xyz="0 0 0" />
            <geometry>
                <mesh filename="package://blue_arm_description/meshes/link_6.STL" />
            </geometry>
            <material name="">
                <color rgba="0.1 0.6 0.8 1" />
            </material>
        </visual>
        <collision>
            <origin rpy="0 0 0" xyz="0 0 0" />
            <geometry>
                <mesh filename="package://blue_arm_description/meshes/link_6.STL" />
            </geometry>
        </collision>
    </link>
    <joint name="joint_6" type="revolute">
        <origin rpy="0 0 0" xyz="0 0 0" />
        <parent link="link_5" />
        <child link="link_6" />
        <axis xyz="0 1 0" />
        <limit effort="1000" lower="-1.7" upper="1.7" velocity="6" />
    </joint>
    <link name="link_7">
        
<inertial>
            <origin rpy="0 0 0" xyz="0 0 0" />
            <mass value="0.1" />
            <inertia ixx="0.01" ixy="0" ixz="0" iyy="0.01" iyz="0" izz="0.01" />
        </inertial>

        <collision>
            <geometry>
                <box size="0.01 0.01 0.01" />
            </geometry>
            <origin rpy="0 0 0" xyz="0 0 0" />
        </collision>
    </link>
    <joint name="joint_7" type="revolute">
        <origin rpy="0 0 0" xyz="0.107 0 0" />
        <parent link="link_6" />
        <child link="link_7" />
        <axis xyz="-1 0 0" />
        <limit effort="1000" lower="-3.1415926" upper="3.1415926" velocity="6" />
    </joint>
    <transmission name="trans_joint_1">
        <type>transmission_interface/SimpleTransmission</type>
        <joint name="joint_1">
            <hardwareInterface>hardware_interface/EffortJointInterface</hardwareInterface>
        </joint>
        <actuator name="joint_1_motor">
            <hardwareInterface>hardware_interface/EffortJointInterface</hardwareInterface>
            <mechanicalReduction>1</mechanicalReduction>
        </actuator>
    </transmission>
    <transmission name="trans_joint_2">
        <type>transmission_interface/SimpleTransmission</type>
        <joint name="joint_2">
            <hardwareInterface>hardware_interface/EffortJointInterface</hardwareInterface>
        </joint>
        <actuator name="joint_2_motor">
            <hardwareInterface>hardware_interface/EffortJointInterface</hardwareInterface>
            <mechanicalReduction>1</mechanicalReduction>
        </actuator>
    </transmission>
    <transmission name="trans_joint_3">
        <type>transmission_interface/SimpleTransmission</type>
        <joint name="joint_3">
            <hardwareInterface>hardware_interface/EffortJointInterface</hardwareInterface>
        </joint>
        <actuator name="joint_3_motor">
            <hardwareInterface>hardware_interface/EffortJointInterface</hardwareInterface>
            <mechanicalReduction>1</mechanicalReduction>
        </actuator>
    </transmission>
    <transmission name="trans_joint_4">
        <type>transmission_interface/SimpleTransmission</type>
        <joint name="joint_4">
            <hardwareInterface>hardware_interface/EffortJointInterface</hardwareInterface>
        </joint>
        <actuator name="joint_4_motor">
            <hardwareInterface>hardware_interface/EffortJointInterface</hardwareInterface>
            <mechanicalReduction>1</mechanicalReduction>
        </actuator>
    </transmission>
    <transmission name="trans_joint_5">
        <type>transmission_interface/SimpleTransmission</type>
        <joint name="joint_5">
            <hardwareInterface>hardware_interface/EffortJointInterface</hardwareInterface>
        </joint>
        <actuator name="joint_5_motor">
            <hardwareInterface>hardware_interface/EffortJointInterface</hardwareInterface>
            <mechanicalReduction>1</mechanicalReduction>
        </actuator>
    </transmission>
    <transmission name="trans_joint_6">
        <type>transmission_interface/SimpleTransmission</type>
        <joint name="joint_6">
            <hardwareInterface>hardware_interface/EffortJointInterface</hardwareInterface>
        </joint>
        <actuator name="joint_6_motor">
            <hardwareInterface>hardware_interface/EffortJointInterface</hardwareInterface>
            <mechanicalReduction>1</mechanicalReduction>
        </actuator>
    </transmission>
    <transmission name="trans_joint_7">
        <type>transmission_interface/SimpleTransmission</type>
        <joint name="joint_7">
            <hardwareInterface>hardware_interface/EffortJointInterface</hardwareInterface>
        </joint>
        <actuator name="joint_7_motor">
            <hardwareInterface>hardware_interface/EffortJointInterface</hardwareInterface>
            <mechanicalReduction>1</mechanicalReduction>
        </actuator>
    </transmission>
    <gazebo>
        <plugin name="gazebo_ros_control" filename="libgazebo_ros_control.so">
            <robotNamespace>/</robotNamespace>
        </plugin>
    </gazebo>
</robot>

<transmission name="transmission_1">
        <type>transmission_interface/SimpleTransmission</type>
        <joint name="joint_1">
            <hardwareInterface>hardware_interface/EffortJointInterface</hardwareInterface>
        </joint>
        <actuator name="motor_1">
            <mechanicalReduction>1</mechanicalReduction>
            <hardwareInterface>hardware_interface/EffortJointInterface</hardwareInterface>
        </actuator>
    </transmission>
    <transmission name="transmission_2">
        <type>transmission_interface/SimpleTransmission</type>
        <joint name="joint_2">
            <hardwareInterface>hardware_interface/EffortJointInterface</hardwareInterface>
        </joint>
        <actuator name="motor_2">
            <mechanicalReduction>1</mechanicalReduction>
            <hardwareInterface>hardware_interface/EffortJointInterface</hardwareInterface>
        </actuator>
    </transmission>
    <transmission name="transmission_3">
        <type>transmission_interface/SimpleTransmission</type>
        <joint name="joint_3">
            <hardwareInterface>hardware_interface/EffortJointInterface</hardwareInterface>
        </joint>
        <actuator name="motor_3">
            <mechanicalReduction>1</mechanicalReduction>
            <hardwareInterface>hardware_interface/EffortJointInterface</hardwareInterface>
        </actuator>
    </transmission>
    <transmission name="transmission_4">
        <type>transmission_interface/SimpleTransmission</type>
        <joint name="joint_4">
            <hardwareInterface>hardware_interface/EffortJointInterface</hardwareInterface>
        </joint>
        <actuator name="motor_4">
            <mechanicalReduction>1</mechanicalReduction>
            <hardwareInterface>hardware_interface/EffortJointInterface</hardwareInterface>
        </actuator>
    </transmission>
    <transmission name="transmission_5">
        <type>transmission_interface/SimpleTransmission</type>
        <joint name="joint_5">
            <hardwareInterface>hardware_interface/EffortJointInterface</hardwareInterface>
        </joint>
        <actuator name="motor_5">
            <mechanicalReduction>1</mechanicalReduction>
            <hardwareInterface>hardware_interface/EffortJointInterface</hardwareInterface>
        </actuator>
    </transmission>
    <transmission name="transmission_6">
        <type>transmission_interface/SimpleTransmission</type>
        <joint name="joint_6">
            <hardwareInterface>hardware_interface/EffortJointInterface</hardwareInterface>
        </joint>
        <actuator name="motor_6">
            <mechanicalReduction>1</mechanicalReduction>
            <hardwareInterface>hardware_interface/EffortJointInterface</hardwareInterface>
        </actuator>
    </transmission>
    <transmission name="transmission_7">
        <type>transmission_interface/SimpleTransmission</type>
        <joint name="joint_7">
            <hardwareInterface>hardware_interface/EffortJointInterface</hardwareInterface>
        </joint>
        <actuator name="motor_7">
            <mechanicalReduction>1</mechanicalReduction>
            <hardwareInterface>hardware_interface/EffortJointInterface</hardwareInterface>
        </actuator>
    </transmission>
    <link name="world" />
    <joint name="joint_0 " type="fixed">
        <origin rpy="0 0 0" xyz="0 0 0" />
        <parent link="world" />
        <child link="base_link" />
    </joint>
    <link name="base_link">
        <inertial>
            <origin rpy="0 0 0" xyz="-1.2721E-09 -2.221E-09 0.029334" />
            <mass value="0.80823" />
            <inertia ixx="0.00092021" ixy="2.0871E-10" ixz="-1.3863E-11" iyy="0.00088788" iyz="-1.2165E-11" izz="0.001593" />
        </inertial>
        <visual>
            <origin rpy="0 0 0" xyz="0 0 0" />
            <geometry>
                <mesh filename="package://blue_arm_description/meshes/base_link.STL" />
            </geometry>
            <material name="">
                <color rgba="0.1 0.6 0.8 1" />
            </material>
        </visual>
        <collision>
            <origin rpy="0 0 0" xyz="0 0 0" />
            <geometry>
                <mesh filename="package://blue_arm_description/meshes/base_link.STL" />
            </geometry>
        </collision>
    </link>
    <link name="link_1">
        <inertial>
            <origin rpy="0 0 0" xyz="0.0013724819847024 0.00105856120896306 -0.0137822751691176" />
            <mass value="0.842297822851205" />
            <inertia ixx="0.00076340953424039" ixy="-3.51636077803791E-06" ixz="-3.95975667675045E-06" iyy="0.00121976980344189" iyz="1.36722548032234E-06" izz="0.00102227900722713" />
        </inertial>
        <visual>
            <origin rpy="0 0 0" xyz="0 0 0" />
            <geometry>
                <mesh filename="package://blue_arm_description/meshes/link_1.STL" />
            </geometry>
            <material name="">
                <color rgba="0.898039215686275 0.917647058823529 0.929411764705882 1" />
            </material>
        </visual>
        <collision>
            <origin rpy="0 0 0" xyz="0 0 0" />
            <geometry>
                <mesh filename="package://blue_arm_description/meshes/link_1.STL" />
            </geometry>
        </collision>
    </link>
    <joint name="joint_1" type="revolute">
        <origin rpy="0 0 0" xyz="0 0 0.14" />
        <parent link="base_link" />
        <child link="link_1" />
        <axis xyz="0 0 1" />
        <limit effort="1000" lower="-3.1415926" upper="3.1415926" velocity="6" />
    </joint>
    <link name="link_2">
        <inertial>
            <origin rpy="0 0 0" xyz="0.0769223200130146 8.08732473817575E-05 -0.00042635625580266" />
            <mass value="0.745981126447571" />
            <inertia ixx="0.000520841610219072" ixy="-4.81334906961203E-06" ixz="-1.95626090273518E-06" iyy="0.00042477641414559" iyz="-5.52016092200821E-06" izz="0.000384489660316636" />
        </inertial>
        <visual>
            <origin rpy="0 0 0" xyz="0 0 0" />
            <geometry>
                <mesh filename="package://blue_arm_description/meshes/link_2.STL" />
            </geometry>
            <material name="">
                <color rgba="0.1 0.6 0.8 1" />
            </material>
        </visual>
        <collision>
            <origin rpy="0 0 0" xyz="0 0 0" />
            <geometry>
                <mesh filename="package://blue_arm_description/meshes/link_2.STL" />
            </geometry>
        </collision>
    </link>
    <joint name="joint_2" type="revolute">
        <origin rpy="0 0 0" xyz="0 0 0" />
        <parent link="link_1" />
        <child link="link_2" />
        <axis xyz="0 -1 0" />
        <limit effort="1000" lower="0" upper="3.1415926" velocity="6" />
    </joint>
    <link name="link_3">
        <inertial>
            <origin rpy="0 0 0" xyz="-0.0114331813251084 -0.000457582008541844 -0.0216566472730735" />
            <mass value="0.804459827803754" />
            <inertia ixx="0.000394716139862203" ixy="1.20034101751916E-06" ixz="-1.15155911130661E-05" iyy="0.000369176277421544" iyz="-1.52204783481967E-06" izz="0.000335294348916886" />
        </inertial>
        <visual>
            <origin rpy="0 0 0" xyz="0 0 0" />
            <geometry>
                <mesh filename="package://blue_arm_description/meshes/link_3.STL" />
            </geometry>
            <material name="">
                <color rgba="0.898039215686275 0.917647058823529 0.929411764705882 1" />
            </material>
        </visual>
        <collision>
            <origin rpy="0 0 0" xyz="0 0 0" />
            <geometry>
                <mesh filename="package://blue_arm_description/meshes/link_3.STL" />
            </geometry>
        </collision>
    </link>
    <joint name="joint_3" type="revolute">
        <origin rpy="0 0 0" xyz="0.19 0 0" />
        <parent link="link_2" />
        <child link="link_3" />
        <axis xyz="-1 0 0" />
        <limit effort="1000" lower="-3.1415926" upper="3.1415926" velocity="6" />
    </joint>
    <link name="link_4">
        <inertial>
            <origin rpy="0 0 0" xyz="0.0769734778463645 0.000934629244450365 0.0356212264841299" />
            <mass value="0.566230423072006" />
            <inertia ixx="0.000323477443788715" ixy="1.29185501358438E-06" ixz="-1.18136439524261E-05" iyy="0.000225583796578213" iyz="-6.10063744425435E-06" izz="0.000221671905453137" />
        </inertial>
        <visual>
            <origin rpy="0 0 0" xyz="0 0 0" />
            <geometry>
                <mesh filename="package://blue_arm_description/meshes/link_4.STL" />
            </geometry>
            <material name="">
                <color rgba="0.1 0.6 0.8 1" />
            </material>
        </visual>
        <collision>
            <origin rpy="0 0 0" xyz="0 0 0" />
            <geometry>
                <mesh filename="package://blue_arm_description/meshes/link_4.STL" />
            </geometry>
        </collision>
    </link>
    <joint name="joint_4" type="revolute">
        <origin rpy="0 0 0" xyz="0 0 -0.0365" />
        <parent link="link_3" />
        <child link="link_4" />
        <axis xyz="0 1 0" />
        <limit effort="1000" lower="0" upper="3.1415926" velocity="6" />
    </joint>
    <link name="link_5">
        <inertial>
            <origin rpy="0 0 0" xyz="-0.0148074583751761 0.00213542128687548 2.18169794868883E-07" />
            <mass value="0.462017126683371" />
            <inertia ixx="0.000177893444569323" ixy="1.32666352831544E-05" ixz="-3.05686863907704E-07" iyy="0.000225592333679048" iyz="1.12464809894113E-09" izz="0.000163107825386613" />
        </inertial>
        <visual>
            <origin rpy="0 0 0" xyz="0 0 0" />
            <geometry>
                <mesh filename="package://blue_arm_description/meshes/link_5.STL" />
            </geometry>
            <material name="">
                <color rgba="0.898039215686275 0.917647058823529 0.929411764705882 1" />
            </material>
        </visual>
        <collision>
            <origin rpy="0 0 0" xyz="0 0 0" />
            <geometry>
                <mesh filename="package://blue_arm_description/meshes/link_5.STL" />
            </geometry>
        </collision>
    </link>
    <joint name="joint_5" type="revolute">
        <origin rpy="0 0 0" xyz="0.183 0 0.0365" />
        <parent link="link_4" />
        <child link="link_5" />
        <axis xyz="-1 0 0" />
        <limit effort="1000" lower="-3.1415926" upper="3.1415926" velocity="6" />
    </joint>
    <link name="link_6">
        <inertial>
            <origin rpy="0 0 0" xyz="0.057311 -0.0040732 2.7725E-07" />
            <mass value="0.41677" />
            <inertia ixx="0.00018847" ixy="-1.4409E-05" ixz="-1.3757E-09" iyy="0.0001068" iyz="-3.057E-07" izz="0.00014801" />
        </inertial>
        <visual>
            <origin rpy="0 0 0" xyz="0 0 0" />
            <geometry>
                <mesh filename="package://blue_arm_description/meshes/link_6.STL" />
            </geometry>
            <material name="">
                <color rgba="0.1 0.6 0.8 1" />
            </material>
        </visual>
        <collision>
            <origin rpy="0 0 0" xyz="0 0 0" />
            <geometry>
                <mesh filename="package://blue_arm_description/meshes/link_6.STL" />
            </geometry>
        </collision>
    </link>
    <joint name="joint_6" type="revolute">
        <origin rpy="0 0 0" xyz="0 0 0" />
        <parent link="link_5" />
        <child link="link_6" />
        <axis xyz="0 1 0" />
        <limit effort="1000" lower="-1.7" upper="1.7" velocity="6" />
    </joint>
    <link name="link_7">
        <inertial>
            <origin rpy="0 0 0" xyz="0 0 0" />
            <mass value="0.1" />
            <inertia ixx="0.01" ixy="0" ixz="0" iyy="0.01" iyz="0" izz="0.01" />
        </inertial>
        <collision>
            <geometry>
                <box size="0.01 0.01 0.01" />
            </geometry>
            <origin rpy="0 0 0" xyz="0 0 0" />
        </collision>
    </link>
    <joint name="joint_7" type="revolute">
        <origin rpy="0 0 0" xyz="0.107 0 0" />
        <parent link="link_6" />
        <child link="link_7" />
        <axis xyz="-1 0 0" />
        <limit effort="1000" lower="-3.1415926" upper="3.1415926" velocity="6" />
    </joint>
    <transmission name="trans_joint_1">
        <type>transmission_interface/SimpleTransmission</type>
        <joint name="joint_1">
            <hardwareInterface>hardware_interface/EffortJointInterface</hardwareInterface>
        </joint>
        <actuator name="joint_1_motor">
            <hardwareInterface>hardware_interface/EffortJointInterface</hardwareInterface>
            <mechanicalReduction>1</mechanicalReduction>
        </actuator>
    </transmission>
    <transmission name="trans_joint_2">
        <type>transmission_interface/SimpleTransmission</type>
        <joint name="joint_2">
            <hardwareInterface>hardware_interface/EffortJointInterface</hardwareInterface>
        </joint>
        <actuator name="joint_2_motor">
            <hardwareInterface>hardware_interface/EffortJointInterface</hardwareInterface>
            <mechanicalReduction>1</mechanicalReduction>
        </actuator>
    </transmission>
    <transmission name="trans_joint_3">
        <type>transmission_interface/SimpleTransmission</type>
        <joint name="joint_3">
            <hardwareInterface>hardware_interface/EffortJointInterface</hardwareInterface>
        </joint>
        <actuator name="joint_3_motor">
            <hardwareInterface>hardware_interface/EffortJointInterface</hardwareInterface>
            <mechanicalReduction>1</mechanicalReduction>
        </actuator>
    </transmission>
    <transmission name="trans_joint_4">
        <type>transmission_interface/SimpleTransmission</type>
        <joint name="joint_4">
            <hardwareInterface>hardware_interface/EffortJointInterface</hardwareInterface>
        </joint>
        <actuator name="joint_4_motor">
            <hardwareInterface>hardware_interface/EffortJointInterface</hardwareInterface>
            <mechanicalReduction>1</mechanicalReduction>
        </actuator>
    </transmission>
    <transmission name="trans_joint_5">
        <type>transmission_interface/SimpleTransmission</type>
        <joint name="joint_5">
            <hardwareInterface>hardware_interface/EffortJointInterface</hardwareInterface>
        </joint>
        <actuator name="joint_5_motor">
            <hardwareInterface>hardware_interface/EffortJointInterface</hardwareInterface>
            <mechanicalReduction>1</mechanicalReduction>
        </actuator>
    </transmission>
    <transmission name="trans_joint_6">
        <type>transmission_interface/SimpleTransmission</type>
        <joint name="joint_6">
            <hardwareInterface>hardware_interface/EffortJointInterface</hardwareInterface>
        </joint>
        <actuator name="joint_6_motor">
            <hardwareInterface>hardware_interface/EffortJointInterface</hardwareInterface>
            <mechanicalReduction>1</mechanicalReduction>
        </actuator>
    </transmission>
    <transmission name="trans_joint_7">
        <type>transmission_interface/SimpleTransmission</type>
        <joint name="joint_7">
            <hardwareInterface>hardware_interface/EffortJointInterface</hardwareInterface>
        </joint>
        <actuator name="joint_7_motor">
            <hardwareInterface>hardware_interface/EffortJointInterface</hardwareInterface>
            <mechanicalReduction>1</mechanicalReduction>
        </actuator>
    </transmission>
    <gazebo>
        <plugin name="gazebo_ros_control" filename="libgazebo_ros_control.so">
            <robotNamespace>/</robotNamespace>
        </plugin>
    </gazebo>
</robot>